Workbook

Sheet Start
B2: FINANCIEEL ANALYSE-DASHBOARD
B3: Managementrapportage handelsonderneming
B5: LOGO | F5: Bedrijfsnaam | H5: ='Instellingen'!$D$6
F6: KvK-nummer | H6: ='Instellingen'!$D$7
F7: Boekjaar | H7: ='Instellingen'!$D$8
F8: Periode | H8: ='Instellingen'!$D$17
F9: Rapportagedatum | H9: ='Instellingen'!$D$9
F10: Versie | H10: 1.0
F11: Accountant | H11: Naam accountant / kantoor
B14: Navigatie
B16: ► Dashboard | F16: ► Resultatenrekening | J16: ► Balans
B17: Managementoverzicht met KPI's | F17: Winst & verlies met vergelijking | J17: Activa en passiva
B19: ► Financiële ratio's | F19: ► Debiteuren | J19: ► Crediteuren
B20: Kengetallen met normering | F20: Ouderdom en top-debiteuren | J20: Betaaltermijn en top-crediteuren
B22: ► Voorraad | F22: ► Trendanalyse | J22: ► Signalering
B23: Rotatie en signalering | F23: 24-maands ontwikkeling | J23: Automatische waarschuwingen
B25: ► Samenvatting | F25: ► Instellingen | J25: ► Brondata
B26: Management­samenvatting | F26: Algemene gegevens & normen | J26: Grootboekexport plakken
B29: Werkwijze: 1) vul Instellingen in · 2) plak de grootboekexport in Brondata · 3) controleer de Mapping. De rest rekent automatisch door.
B30: Model rekent met SUMIFS/INDEX/MATCH (geen macro's, geen VBA). Open in Excel voor de volledige, dynamische werking.

Sheet Instellingen
A1: INSTELLINGEN
A2: Start | C2: Dashboard | E2: Resultaat | G2: Balans | I2: Ratio's | K2: Debiteuren | M2: Crediteuren | O2: Voorraad | Q2: Trend | S2: Signalering | U2: Samenvatting
A3: Pas hier de algemene gegevens, selecties, weergave en normeringen aan. Invulvelden zijn lichtgroen.
B5: Algemene gegevens | M5: Januari | N5: 1 | P5: Euro's | Q5: 1 | R5: €
B6: Bedrijfsnaam | D6: Handelsonderneming Voorbeeld B.V. | M6: Februari | N6: 2 | P6: Duizenden | Q6: 1000 | R6: € (x1.000)
B7: KvK-nummer | D7: 12345678 | M7: Maart | N7: 3 | P7: Miljoenen | Q7: 1000000 | R7: € (mln)
B8: Boekjaar | D8: 2025 | M8: April | N8: 4
B9: Rapportagedatum | D9: 46022 | M9: Mei | N9: 5
B10: Begindatum | D10: 45658 | M10: Juni | N10: 6
B11: Einddatum | D11: 46022 | M11: Juli | N11: 7
B12: Vergelijkingsjaar | D12: 2024 | M12: Augustus | N12: 8
B13: BTW-periode | D13: Per kwartaal | M13: September | N13: 9
B14: Valuta | D14: EUR (€) | M14: Oktober | N14: 10
M15: November | N15: 11
B16: Selecties | M16: December | N16: 12
B17: Periode (t/m) | D17: Heel jaar | E17: → t/m maand: | F17: =IFERROR(INDEX($N$5:$N$23,MATCH($D$17,$M$5:$M$23,0)),12) | M17: Kwartaal 1 | N17: 3
B18: Vergelijking | D18: Vorig jaar | M18: Kwartaal 2 | N18: 6
M19: Kwartaal 3 | N19: 9
B20: Weergave-instellingen | M20: Kwartaal 4 | N20: 12
B21: BTW-weergave | D21: Exclusief BTW | M21: Halfjaar 1 | N21: 6
B22: Afronding | D22: Euro's | F22: =IFERROR(INDEX($Q$5:$Q$7,MATCH($D$22,$P$5:$P$7,0)),1) | G22: =IFERROR(INDEX($R$5:$R$7,MATCH($D$22,$P$5:$P$7,0)),"€") | M22: Halfjaar 2 | N22: 12
B23: Negatieve bedragen rood | D23: Ja | M23: Heel jaar | N23: 12
B25: Normeringen (signaleringen)
B26: Kengetal | D26: Norm
B27: Brutomarge % | D27: 0.28
B28: Nettomarge % | D28: 0.04
B29: Current ratio | D29: 1.5
B30: Quick ratio | D30: 1
B31: Solvabiliteit % | D31: 0.3
B32: Rentabiliteit EV % | D32: 0.1
B33: Omloopsnelheid voorraad | D33: 5
B34: DSO (dagen) | D34: 45
B35: DPO (dagen) | D35: 45
B36: Werkkapitaal (€) | D36: 250000
B38: Let op: gebruik XLOOKUP/FILTER niet nodig — model rekent met SUMIFS/INDEX/MATCH; plak data in Brondata.

Sheet Brondata
A1: BRONDATA
A2: Plak hier de grootboekexport (kolommen A t/m H en J t/m N). Saldo en Dashboardcategorie worden automatisch berekend — niet overschrijven.
A4: Datum | B4: Grootboek | C4: Omschrijving | D4: Kostenplaats | E4: Kostendrager | F4: Relatie | G4: Debet | H4: Credit | I4: Saldo | J4: Boekjaar | K4: Periode | L4: Categorie | M4: Rubriek | N4: Subrubriek | O4: Dashboardcategorie
A5: 45292 | B5: 8000 | C5: Omzet handelsgoederen hoog | D5: Verkoop | E5: Algemeen | G5: 0 | H5: 171500 | I5: =G5-H5 | J5: 2024 | K5: 1 | L5: Winst- en verliesrekening | M5: Netto-omzet | N5: Handel hoog tarief | O5: =IFERROR(INDEX('Mapping'!$F$2:$F$60,MATCH(B5,'Mapping'!$A$2:$A$60,0)),"")
A6: 45323 | B6: 8000 | C6: Omzet handelsgoederen hoog | D6: Verkoop | E6: Algemeen | G6: 0 | H6: 171500 | I6: =G6-H6 | J6: 2024 | K6: 2 | L6: Winst- en verliesrekening | M6: Netto-omzet | N6: Handel hoog tarief | O6: =IFERROR(INDEX('Mapping'!$F$2:$F$60,MATCH(B6,'Mapping'!$A$2:$A$60,0)),"")
A7: 45352 | B7: 8000 | C7: Omzet handelsgoederen hoog | D7: Verkoop | E7: Algemeen | G7: 0 | H7: 215600 | I7: =G7-H7 | J7: 2024 | K7: 3 | L7: Winst- en verliesrekening | M7: Netto-omzet | N7: Handel hoog tarief | O7: =IFERROR(INDEX('Mapping'!$F$2:$F$60,MATCH(B7,'Mapping'!$A$2:$A$60,0)),"")
A8: 45383 | B8: 8000 | C8: Omzet handelsgoederen hoog | D8: Verkoop | E8: Algemeen | G8: 0 | H8: 200900 | I8: =G8-H8 | J8: 2024 | K8: 4 | L8: Winst- en verliesrekening | M8: Netto-omzet | N8: Handel hoog tarief | O8: =IFERROR(INDEX('Mapping'!$F$2:$F$60,MATCH(B8,'Mapping'!$A$2:$A$60,0)),"")
A9: 45413 | B9: 8000 | C9: Omzet handelsgoederen hoog | D9: Verkoop | E9: Algemeen | G9: 0 | H9: 210700 | I9: =G9-H9 | J9: 2024 | K9: 5 | L9: Winst- en verliesrekening | M9: Netto-omzet | N9: Handel hoog tarief | O9: =IFERROR(INDEX('Mapping'!$F$2:$F$60,MATCH(B9,'Mapping'!$A$2:$A$60,0)),"")
A10: 45444 | B10: 8000 | C10: Omzet handelsgoederen hoog | D10: Verkoop | E10: Algemeen | G10: 0 | H10: 220500 | I10: =G10-H10 | J10: 2024 | K10: 6 | L10: Winst- en verliesrekening | M10: Netto-omzet | N10: Handel hoog tarief | O10: =IFERROR(INDEX('Mapping'!$F$2:$F$60,MATCH(B10,'Mapping'!$A$2:$A$60,0)),"")
A11: 45474 | B11: 8000 | C11: Omzet handelsgoederen hoog | D11: Verkoop | E11: Algemeen | G11: 0 | H11: 186200 | I11: =G11-H11 | J11: 2024 | K11: 7 | L11: Winst- en verliesrekening | M11: Netto-omzet | N11: Handel hoog tarief | O11: =IFERROR(INDEX('Mapping'!$F$2:$F$60,MATCH(B11,'Mapping'!$A$2:$A$60,0)),"")
A12: 45505 | B12: 8000 | C12: Omzet handelsgoederen hoog | D12: Verkoop | E12: Algemeen | G12: 0 | H12: 171500 | I12: =G12-H12 | J12: 2024 | K12: 8 | L12: Winst- en verliesrekening | M12: Netto-omzet | N12: Handel hoog tarief | O12: =IFERROR(INDEX('Mapping'!$F$2:$F$60,MATCH(B12,'Mapping'!$A$2:$A$60,0)),"")
A13: 45536 | B13: 8000 | C13: Omzet handelsgoederen hoog | D13: Verkoop | E13: Algemeen | G13: 0 | H13: 215600 | I13: =G13-H13 | J13: 2024 | K13: 9 | L13: Winst- en verliesrekening | M13: Netto-omzet | N13: Handel hoog tarief | O13: =IFERROR(INDEX('Mapping'!$F$2:$F$60,MATCH(B13,'Mapping'!$A$2:$A$60,0)),"")
A14: 45566 | B14: 8000 | C14: Omzet handelsgoederen hoog | D14: Verkoop | E14: Algemeen | G14: 0 | H14: 220500 | I14: =G14-H14 | J14: 2024 | K14: 10 | L14: Winst- en verliesrekening | M14: Netto-omzet | N14: Handel hoog tarief | O14: =IFERROR(INDEX('Mapping'!$F$2:$F$60,MATCH(B14,'Mapping'!$A$2:$A$60,0)),"")
A15: 45597 | B15: 8000 | C15: Omzet handelsgoederen hoog | D15: Verkoop | E15: Algemeen | G15: 0 | H15: 210700 | I15: =G15-H15 | J15: 2024 | K15: 11 | L15: Winst- en verliesrekening | M15: Netto-omzet | N15: Handel hoog tarief | O15: =IFERROR(INDEX('Mapping'!$F$2:$F$60,MATCH(B15,'Mapping'!$A$2:$A$60,0)),"")
A16: 45627 | B16: 8000 | C16: Omzet handelsgoederen hoog | D16: Verkoop | E16: Algemeen | G16: 0 | H16: 254800 | I16: =G16-H16 | J16: 2024 | K16: 12 | L16: Winst- en verliesrekening | M16: Netto-omzet | N16: Handel hoog tarief | O16: =IFERROR(INDEX('Mapping'!$F$2:$F$60,MATCH(B16,'Mapping'!$A$2:$A$60,0)),"")
... A990: 45992 | B990: 1700 | C990: Overige schulden | D990: Balans | E990: Balans | G990: 0 | H990: 1040 | I990: =G990-H990 | J990: 2025 | K990: 12 | L990: Balans | M990: Kortlopende schulden | N990: Overlopende passiva | O990: =IFERROR(INDEX('Mapping'!$F$2:$F$60,MATCH(B990,'Mapping'!$A$2:$A$60,0)),"")
I991: =G991-H991 | O991: =IFERROR(INDEX('Mapping'!$F$2:$F$60,MATCH(B991,'Mapping'!$A$2:$A$60,0)),"")
I992: =G992-H992 | O992: =IFERROR(INDEX('Mapping'!$F$2:$F$60,MATCH(B992,'Mapping'!$A$2:$A$60,0)),"")
I993: =G993-H993 | O993: =IFERROR(INDEX('Mapping'!$F$2:$F$60,MATCH(B993,'Mapping'!$A$2:$A$60,0)),"")
I994: =G994-H994 | O994: =IFERROR(INDEX('Mapping'!$F$2:$F$60,MATCH(B994,'Mapping'!$A$2:$A$60,0)),"")
I995: =G995-H995 | O995: =IFERROR(INDEX('Mapping'!$F$2:$F$60,MATCH(B995,'Mapping'!$A$2:$A$60,0)),"")
I996: =G996-H996 | O996: =IFERROR(INDEX('Mapping'!$F$2:$F$60,MATCH(B996,'Mapping'!$A$2:$A$60,0)),"")
I997: =G997-H997 | O997: =IFERROR(INDEX('Mapping'!$F$2:$F$60,MATCH(B997,'Mapping'!$A$2:$A$60,0)),"")
I998: =G998-H998 | O998: =IFERROR(INDEX('Mapping'!$F$2:$F$60,MATCH(B998,'Mapping'!$A$2:$A$60,0)),"")
I999: =G999-H999 | O999: =IFERROR(INDEX('Mapping'!$F$2:$F$60,MATCH(B999,'Mapping'!$A$2:$A$60,0)),"")
I1000: =G1000-H1000 | O1000: =IFERROR(INDEX('Mapping'!$F$2:$F$60,MATCH(B1000,'Mapping'!$A$2:$A$60,0)),"")
I1001: =G1001-H1001 | O1001: =IFERROR(INDEX('Mapping'!$F$2:$F$60,MATCH(B1001,'Mapping'!$A$2:$A$60,0)),"")
I1002: =G1002-H1002 | O1002: =IFERROR(INDEX('Mapping'!$F$2:$F$60,MATCH(B1002,'Mapping'!$A$2:$A$60,0)),"")
... I1504: =G1504-H1504 | O1504: =IFERROR(INDEX('Mapping'!$F$2:$F$60,MATCH(B1504,'Mapping'!$A$2:$A$60,0)),"")

Sheet Mapping
A1: MAPPING GROOTBOEK → DASHBOARDCATEGORIE
A2: Vrij aanpasbaar. Elke grootboekrekening koppelt aan één dashboardcategorie.
A4: Grootboek | B4: Omschrijving | C4: Balans/W&V | D4: Hoofdcategorie | E4: Subcategorie | F4: Dashboardcategorie
A5: 8000 | B5: Omzet handelsgoederen hoog | C5: Winst- en verliesrekening | D5: Netto-omzet | E5: Handel hoog tarief | F5: Omzet
A6: 8010 | B6: Omzet handelsgoederen laag | C6: Winst- en verliesrekening | D6: Netto-omzet | E6: Handel laag tarief | F6: Omzet
A7: 8020 | B7: Omzet dienstverlening | C7: Winst- en verliesrekening | D7: Netto-omzet | E7: Diensten | F7: Omzet
A8: 7000 | B8: Inkoopwaarde handelsgoederen | C8: Winst- en verliesrekening | D8: Kostprijs omzet | E8: Inkoop goederen | F8: Inkoopwaarde
A9: 7010 | B9: Inkoopkosten en vracht | C9: Winst- en verliesrekening | D9: Kostprijs omzet | E9: Vracht en inkoop | F9: Inkoopwaarde
A10: 4000 | B10: Brutolonen | C10: Winst- en verliesrekening | D10: Personeelskosten | E10: Lonen | F10: Personeelskosten
A11: 4010 | B11: Sociale lasten | C11: Winst- en verliesrekening | D11: Personeelskosten | E11: Sociale lasten | F11: Personeelskosten
A12: 4020 | B12: Pensioenlasten | C12: Winst- en verliesrekening | D12: Personeelskosten | E12: Pensioen | F12: Personeelskosten
A13: 4030 | B13: Overige personeelskosten | C13: Winst- en verliesrekening | D13: Personeelskosten | E13: Overig personeel | F13: Personeelskosten
A14: 4100 | B14: Huur bedrijfspand | C14: Winst- en verliesrekening | D14: Huisvestingskosten | E14: Huur | F14: Huisvesting
A15: 4110 | B15: Energie en water | C15: Winst- en verliesrekening | D15: Huisvestingskosten | E15: Energie | F15: Huisvesting
A16: 4120 | B16: Onderhoud pand | C16: Winst- en verliesrekening | D16: Huisvestingskosten | E16: Onderhoud | F16: Huisvesting
... A44: 1700 | B44: Overige schulden | C44: Balans | D44: Kortlopende schulden | E44: Overlopende passiva | F44: Overige schulden

Sheet Dashboard
A1: MANAGEMENTDASHBOARD
A2: Start | C2: Dashboard | E2: Resultaat | G2: Balans | I2: Ratio's | K2: Debiteuren | M2: Crediteuren | O2: Voorraad | Q2: Trend | S2: Signalering | U2: Samenvatting
A3: =('Instellingen'!$D$6)&" · Boekjaar "&('Instellingen'!$D$8)&" · Periode t/m "&('Instellingen'!$D$17)&" · Bedragen in "&('Instellingen'!$G$22)
B5: OMZET | E5: BRUTOWINST | H5: BRUTOMARGE | K5: EBITDA
B6: ='Resultatenrekening'!$C$7/'Instellingen'!$F$22 | E6: ='Resultatenrekening'!$C$9/'Instellingen'!$F$22 | H6: ='Resultatenrekening'!$C$24 | K6: ='Resultatenrekening'!$C$23/'Instellingen'!$F$22
B8: =IFERROR((('Resultatenrekening'!$C$7)-('Resultatenrekening'!$D$7))/ABS('Resultatenrekening'!$D$7),0) | E8: =IFERROR((('Resultatenrekening'!$C$9)-('Resultatenrekening'!$D$9))/ABS('Resultatenrekening'!$D$9),0) | H8: =IFERROR(('Resultatenrekening'!$C$24)-('Resultatenrekening'!$D$24),0) | K8: =IFERROR((('Resultatenrekening'!$C$23)-('Resultatenrekening'!$D$23))/ABS('Resultatenrekening'!$D$23),0)
B10: NETTO RESULTAAT | E10: LIQUIDITEIT (CR) | H10: WERKKAPITAAL | K10: EIGEN VERMOGEN
B11: ='Resultatenrekening'!$C$21/'Instellingen'!$F$22 | E11: =IFERROR('Balans'!$C$16/'Balans'!$C$24,0) | H11: =('Balans'!$C$16-'Balans'!$C$24)/'Instellingen'!$F$22 | K11: ='Balans'!$C$20/'Instellingen'!$F$22
B13: =IFERROR((('Resultatenrekening'!$C$21)-('Resultatenrekening'!$D$21))/ABS('Resultatenrekening'!$D$21),0) | E13: =IFERROR((IFERROR('Balans'!$C$16/'Balans'!$C$24,0))-(IFERROR('Balans'!$D$16/'Balans'!$D$24,0)),0) | H13: =IFERROR(((('Balans'!$C$16-'Balans'!$C$24))-(('Balans'!$D$16-'Balans'!$D$24)))/ABS(('Balans'!$D$16-'Balans'!$D$24)),0) | K13: =IFERROR((('Balans'!$C$20)-('Balans'!$D$20))/ABS('Balans'!$D$20),0)
B15: VOORRAAD | E15: DEBITEUREN | H15: CREDITEUREN | K15: CASHPOSITIE
B16: ='Balans'!$C$12/'Instellingen'!$F$22 | E16: ='Balans'!$C$13/'Instellingen'!$F$22 | H16: ='Balans'!$C$22/'Instellingen'!$F$22 | K16: ='Balans'!$C$15/'Instellingen'!$F$22
B18: =IFERROR((('Balans'!$C$12)-('Balans'!$D$12))/ABS('Balans'!$D$12),0) | E18: =IFERROR((('Balans'!$C$13)-('Balans'!$D$13))/ABS('Balans'!$D$13),0) | H18: =IFERROR((('Balans'!$C$22)-('Balans'!$D$22))/ABS('Balans'!$D$22),0) | K18: =IFERROR((('Balans'!$C$15)-('Balans'!$D$15))/ABS('Balans'!$D$15),0)

Sheet Resultatenrekening
A1: RESULTATENREKENING
A2: Start | C2: Dashboard | E2: Resultaat | G2: Balans | I2: Ratio's | K2: Debiteuren | M2: Crediteuren | O2: Voorraad | Q2: Trend | S2: Signalering | U2: Samenvatting
A3: =('Instellingen'!$D$6)&" · t/m "&('Instellingen'!$D$17)&" "&('Instellingen'!$D$8)&" (vergelijking: "&('Instellingen'!$D$12)&")"
B6: Post | C6: Huidig (t/m periode) | D6: Vorig jaar | E6: Verschil € | F6: Verschil % | G6: % van omzet
B7: Netto-omzet | C7: =-SUMIFS('Brondata'!$I$5:$I$1504,'Brondata'!$O$5:$O$1504,"Omzet",'Brondata'!$J$5:$J$1504,'Instellingen'!$D$8,'Brondata'!$K$5:$K$1504,">=1",'Brondata'!$K$5:$K$1504,"<="&'Instellingen'!$F$17) | D7: =-SUMIFS('Brondata'!$I$5:$I$1504,'Brondata'!$O$5:$O$1504,"Omzet",'Brondata'!$J$5:$J$1504,'Instellingen'!$D$12,'Brondata'!$K$5:$K$1504,">=1",'Brondata'!$K$5:$K$1504,"<="&'Instellingen'!$F$17) | E7: =C7-D7 | F7: =IFERROR((C7-D7)/ABS(D7),0) | G7: =IFERROR(C7/C$7,0)
B8: Inkoopwaarde van de omzet | C8: =SUMIFS('Brondata'!$I$5:$I$1504,'Brondata'!$O$5:$O$1504,"Inkoopwaarde",'Brondata'!$J$5:$J$1504,'Instellingen'!$D$8,'Brondata'!$K$5:$K$1504,">=1",'Brondata'!$K$5:$K$1504,"<="&'Instellingen'!$F$17) | D8: =SUMIFS('Brondata'!$I$5:$I$1504,'Brondata'!$O$5:$O$1504,"Inkoopwaarde",'Brondata'!$J$5:$J$1504,'Instellingen'!$D$12,'Brondata'!$K$5:$K$1504,">=1",'Brondata'!$K$5:$K$1504,"<="&'Instellingen'!$F$17) | E8: =C8-D8 | F8: =IFERROR((C8-D8)/ABS(D8),0) | G8: =IFERROR(C8/C$7,0)
B9: Brutowinst | C9: =C7-C8 | D9: =D7-D8 | E9: =C9-D9 | F9: =IFERROR((C9-D9)/ABS(D9),0) | G9: =IFERROR(C9/C$7,0)
B11: Personeelskosten | C11: =SUMIFS('Brondata'!$I$5:$I$1504,'Brondata'!$O$5:$O$1504,"Personeelskosten",'Brondata'!$J$5:$J$1504,'Instellingen'!$D$8,'Brondata'!$K$5:$K$1504,">=1",'Brondata'!$K$5:$K$1504,"<="&'Instellingen'!$F$17) | D11: =SUMIFS('Brondata'!$I$5:$I$1504,'Brondata'!$O$5:$O$1504,"Personeelskosten",'Brondata'!$J$5:$J$1504,'Instellingen'!$D$12,'Brondata'!$K$5:$K$1504,">=1",'Brondata'!$K$5:$K$1504,"<="&'Instellingen'!$F$17) | E11: =C11-D11 | F11: =IFERROR((C11-D11)/ABS(D11),0) | G11: =IFERROR(C11/C$7,0)
B12: Huisvestingskosten | C12: =SUMIFS('Brondata'!$I$5:$I$1504,'Brondata'!$O$5:$O$1504,"Huisvesting",'Brondata'!$J$5:$J$1504,'Instellingen'!$D$8,'Brondata'!$K$5:$K$1504,">=1",'Brondata'!$K$5:$K$1504,"<="&'Instellingen'!$F$17) | D12: =SUMIFS('Brondata'!$I$5:$I$1504,'Brondata'!$O$5:$O$1504,"Huisvesting",'Brondata'!$J$5:$J$1504,'Instellingen'!$D$12,'Brondata'!$K$5:$K$1504,">=1",'Brondata'!$K$5:$K$1504,"<="&'Instellingen'!$F$17) | E12: =C12-D12 | F12: =IFERROR((C12-D12)/ABS(D12),0) | G12: =IFERROR(C12/C$7,0)
B13: Autokosten | C13: =SUMIFS('Brondata'!$I$5:$I$1504,'Brondata'!$O$5:$O$1504,"Autokosten",'Brondata'!$J$5:$J$1504,'Instellingen'!$D$8,'Brondata'!$K$5:$K$1504,">=1",'Brondata'!$K$5:$K$1504,"<="&'Instellingen'!$F$17) | D13: =SUMIFS('Brondata'!$I$5:$I$1504,'Brondata'!$O$5:$O$1504,"Autokosten",'Brondata'!$J$5:$J$1504,'Instellingen'!$D$12,'Brondata'!$K$5:$K$1504,">=1",'Brondata'!$K$5:$K$1504,"<="&'Instellingen'!$F$17) | E13: =C13-D13 | F13: =IFERROR((C13-D13)/ABS(D13),0) | G13: =IFERROR(C13/C$7,0)
B14: Verkoopkosten | C14: =SUMIFS('Brondata'!$I$5:$I$1504,'Brondata'!$O$5:$O$1504,"Verkoopkosten",'Brondata'!$J$5:$J$1504,'Instellingen'!$D$8,'Brondata'!$K$5:$K$1504,">=1",'Brondata'!$K$5:$K$1504,"<="&'Instellingen'!$F$17) | D14: =SUMIFS('Brondata'!$I$5:$I$1504,'Brondata'!$O$5:$O$1504,"Verkoopkosten",'Brondata'!$J$5:$J$1504,'Instellingen'!$D$12,'Brondata'!$K$5:$K$1504,">=1",'Brondata'!$K$5:$K$1504,"<="&'Instellingen'!$F$17) | E14: =C14-D14 | F14: =IFERROR((C14-D14)/ABS(D14),0) | G14: =IFERROR(C14/C$7,0)
B15: Kantoorkosten | C15: =SUMIFS('Brondata'!$I$5:$I$1504,'Brondata'!$O$5:$O$1504,"Kantoorkosten",'Brondata'!$J$5:$J$1504,'Instellingen'!$D$8,'Brondata'!$K$5:$K$1504,">=1",'Brondata'!$K$5:$K$1504,"<="&'Instellingen'!$F$17) | D15: =SUMIFS('Brondata'!$I$5:$I$1504,'Brondata'!$O$5:$O$1504,"Kantoorkosten",'Brondata'!$J$5:$J$1504,'Instellingen'!$D$12,'Brondata'!$K$5:$K$1504,">=1",'Brondata'!$K$5:$K$1504,"<="&'Instellingen'!$F$17) | E15: =C15-D15 | F15: =IFERROR((C15-D15)/ABS(D15),0) | G15: =IFERROR(C15/C$7,0)
B16: Algemene kosten | C16: =SUMIFS('Brondata'!$I$5:$I$1504,'Brondata'!$O$5:$O$1504,"Algemene kosten",'Brondata'!$J$5:$J$1504,'Instellingen'!$D$8,'Brondata'!$K$5:$K$1504,">=1",'Brondata'!$K$5:$K$1504,"<="&'Instellingen'!$F$17) | D16: =SUMIFS('Brondata'!$I$5:$I$1504,'Brondata'!$O$5:$O$1504,"Algemene kosten",'Brondata'!$J$5:$J$1504,'Instellingen'!$D$12,'Brondata'!$K$5:$K$1504,">=1",'Brondata'!$K$5:$K$1504,"<="&'Instellingen'!$F$17) | E16: =C16-D16 | F16: =IFERROR((C16-D16)/ABS(D16),0) | G16: =IFERROR(C16/C$7,0)
B17: Afschrijvingen | C17: =SUMIFS('Brondata'!$I$5:$I$1504,'Brondata'!$O$5:$O$1504,"Afschrijvingen",'Brondata'!$J$5:$J$1504,'Instellingen'!$D$8,'Brondata'!$K$5:$K$1504,">=1",'Brondata'!$K$5:$K$1504,"<="&'Instellingen'!$F$17) | D17: =SUMIFS('Brondata'!$I$5:$I$1504,'Brondata'!$O$5:$O$1504,"Afschrijvingen",'Brondata'!$J$5:$J$1504,'Instellingen'!$D$12,'Brondata'!$K$5:$K$1504,">=1",'Brondata'!$K$5:$K$1504,"<="&'Instellingen'!$F$17) | E17: =C17-D17 | F17: =IFERROR((C17-D17)/ABS(D17),0) | G17: =IFERROR(C17/C$7,0)
B18: Totaal bedrijfslasten | C18: =SUM(C11:C17) | D18: =SUM(D11:D17) | E18: =C18-D18 | F18: =IFERROR((C18-D18)/ABS(D18),0) | G18: =IFERROR(C18/C$7,0)
B19: Bedrijfsresultaat (EBIT) | C19: =C9-C18 | D19: =D9-D18 | E19: =C19-D19 | F19: =IFERROR((C19-D19)/ABS(D19),0) | G19: =IFERROR(C19/C$7,0)
B20: Financiële baten en lasten | C20: =SUMIFS('Brondata'!$I$5:$I$1504,'Brondata'!$O$5:$O$1504,"Financiele baten en lasten",'Brondata'!$J$5:$J$1504,'Instellingen'!$D$8,'Brondata'!$K$5:$K$1504,">=1",'Brondata'!$K$5:$K$1504,"<="&'Instellingen'!$F$17) | D20: =SUMIFS('Brondata'!$I$5:$I$1504,'Brondata'!$O$5:$O$1504,"Financiele baten en lasten",'Brondata'!$J$5:$J$1504,'Instellingen'!$D$12,'Brondata'!$K$5:$K$1504,">=1",'Brondata'!$K$5:$K$1504,"<="&'Instellingen'!$F$17) | E20: =C20-D20 | F20: =IFERROR((C20-D20)/ABS(D20),0) | G20: =IFERROR(C20/C$7,0)
B21: Resultaat voor belasting | C21: =C19-C20 | D21: =D19-D20 | E21: =C21-D21 | F21: =IFERROR((C21-D21)/ABS(D21),0) | G21: =IFERROR(C21/C$7,0)
B23: EBITDA (indicatief) | C23: =C19+C17 | D23: =D19+D17 | E23: =C23-D23 | F23: =IFERROR((C23-D23)/ABS(D23),0) | G23: =IFERROR(C23/C$7,0)
B24: Brutomarge % | C24: =IFERROR(C9/C7,0) | D24: =IFERROR(D9/D7,0) | E24: =C24-D24

Sheet Balans
A1: BALANS
A2: Start | C2: Dashboard | E2: Resultaat | G2: Balans | I2: Ratio's | K2: Debiteuren | M2: Crediteuren | O2: Voorraad | Q2: Trend | S2: Signalering | U2: Samenvatting
A3: =('Instellingen'!$D$6)&" · per "&TEXT('Instellingen'!$D$11,"dd-mm-yyyy")&" (vergelijking "&('Instellingen'!$D$12)&")"
B6: Post | C6: Huidig | D6: Vorig jaar | E6: Mutatie € | F6: Mutatie %
B7: VASTE ACTIVA
B8: Materiële vaste activa | C8: =SUMIFS('Brondata'!$I$5:$I$1504,'Brondata'!$O$5:$O$1504,"Materiele vaste activa",'Brondata'!$J$5:$J$1504,'Instellingen'!$D$8,'Brondata'!$K$5:$K$1504,"<="&'Instellingen'!$F$17) | D8: =SUMIFS('Brondata'!$I$5:$I$1504,'Brondata'!$O$5:$O$1504,"Materiele vaste activa",'Brondata'!$J$5:$J$1504,'Instellingen'!$D$12,'Brondata'!$K$5:$K$1504,"<="&'Instellingen'!$F$17) | E8: =C8-D8 | F8: =IFERROR((C8-D8)/ABS(D8),0)
B9: Immateriële vaste activa | C9: =SUMIFS('Brondata'!$I$5:$I$1504,'Brondata'!$O$5:$O$1504,"Immateriele vaste activa",'Brondata'!$J$5:$J$1504,'Instellingen'!$D$8,'Brondata'!$K$5:$K$1504,"<="&'Instellingen'!$F$17) | D9: =SUMIFS('Brondata'!$I$5:$I$1504,'Brondata'!$O$5:$O$1504,"Immateriele vaste activa",'Brondata'!$J$5:$J$1504,'Instellingen'!$D$12,'Brondata'!$K$5:$K$1504,"<="&'Instellingen'!$F$17) | E9: =C9-D9 | F9: =IFERROR((C9-D9)/ABS(D9),0)
B10: Totaal vaste activa | C10: =C8+C9 | D10: =D8+D9 | E10: =C10-D10 | F10: =IFERROR((C10-D10)/ABS(D10),0)
B11: VLOTTENDE ACTIVA
B12: Voorraden | C12: =SUMIFS('Brondata'!$I$5:$I$1504,'Brondata'!$O$5:$O$1504,"Voorraden",'Brondata'!$J$5:$J$1504,'Instellingen'!$D$8,'Brondata'!$K$5:$K$1504,"<="&'Instellingen'!$F$17) | D12: =SUMIFS('Brondata'!$I$5:$I$1504,'Brondata'!$O$5:$O$1504,"Voorraden",'Brondata'!$J$5:$J$1504,'Instellingen'!$D$12,'Brondata'!$K$5:$K$1504,"<="&'Instellingen'!$F$17) | E12: =C12-D12 | F12: =IFERROR((C12-D12)/ABS(D12),0)
B13: Debiteuren | C13: =SUMIFS('Brondata'!$I$5:$I$1504,'Brondata'!$O$5:$O$1504,"Debiteuren",'Brondata'!$J$5:$J$1504,'Instellingen'!$D$8,'Brondata'!$K$5:$K$1504,"<="&'Instellingen'!$F$17) | D13: =SUMIFS('Brondata'!$I$5:$I$1504,'Brondata'!$O$5:$O$1504,"Debiteuren",'Brondata'!$J$5:$J$1504,'Instellingen'!$D$12,'Brondata'!$K$5:$K$1504,"<="&'Instellingen'!$F$17) | E13: =C13-D13 | F13: =IFERROR((C13-D13)/ABS(D13),0)
B14: Overige vorderingen | C14: =SUMIFS('Brondata'!$I$5:$I$1504,'Brondata'!$O$5:$O$1504,"Overige vorderingen",'Brondata'!$J$5:$J$1504,'Instellingen'!$D$8,'Brondata'!$K$5:$K$1504,"<="&'Instellingen'!$F$17) | D14: =SUMIFS('Brondata'!$I$5:$I$1504,'Brondata'!$O$5:$O$1504,"Overige vorderingen",'Brondata'!$J$5:$J$1504,'Instellingen'!$D$12,'Brondata'!$K$5:$K$1504,"<="&'Instellingen'!$F$17) | E14: =C14-D14 | F14: =IFERROR((C14-D14)/ABS(D14),0)
B15: Liquide middelen | C15: =SUMIFS('Brondata'!$I$5:$I$1504,'Brondata'!$O$5:$O$1504,"Liquide middelen",'Brondata'!$J$5:$J$1504,'Instellingen'!$D$8,'Brondata'!$K$5:$K$1504,"<="&'Instellingen'!$F$17) | D15: =SUMIFS('Brondata'!$I$5:$I$1504,'Brondata'!$O$5:$O$1504,"Liquide middelen",'Brondata'!$J$5:$J$1504,'Instellingen'!$D$12,'Brondata'!$K$5:$K$1504,"<="&'Instellingen'!$F$17) | E15: =C15-D15 | F15: =IFERROR((C15-D15)/ABS(D15),0)
B16: Totaal vlottende activa | C16: =SUM(C12:C15) | D16: =SUM(D12:D15) | E16: =C16-D16 | F16: =IFERROR((C16-D16)/ABS(D16),0)
B17: TOTAAL ACTIVA | C17: =C10+C16 | D17: =D10+D16 | E17: =C17-D17 | F17: =IFERROR((C17-D17)/ABS(D17),0)
B19: PASSIVA
B20: Eigen vermogen | C20: =-SUMIFS('Brondata'!$I$5:$I$1504,'Brondata'!$O$5:$O$1504,"Eigen vermogen",'Brondata'!$J$5:$J$1504,'Instellingen'!$D$8,'Brondata'!$K$5:$K$1504,"<="&'Instellingen'!$F$17) | D20: =-SUMIFS('Brondata'!$I$5:$I$1504,'Brondata'!$O$5:$O$1504,"Eigen vermogen",'Brondata'!$J$5:$J$1504,'Instellingen'!$D$12,'Brondata'!$K$5:$K$1504,"<="&'Instellingen'!$F$17) | E20: =C20-D20 | F20: =IFERROR((C20-D20)/ABS(D20),0)
B21: Langlopende schulden | C21: =-SUMIFS('Brondata'!$I$5:$I$1504,'Brondata'!$O$5:$O$1504,"Langlopende schulden",'Brondata'!$J$5:$J$1504,'Instellingen'!$D$8,'Brondata'!$K$5:$K$1504,"<="&'Instellingen'!$F$17) | D21: =-SUMIFS('Brondata'!$I$5:$I$1504,'Brondata'!$O$5:$O$1504,"Langlopende schulden",'Brondata'!$J$5:$J$1504,'Instellingen'!$D$12,'Brondata'!$K$5:$K$1504,"<="&'Instellingen'!$F$17) | E21: =C21-D21 | F21: =IFERROR((C21-D21)/ABS(D21),0)
B22: Crediteuren | C22: =-SUMIFS('Brondata'!$I$5:$I$1504,'Brondata'!$O$5:$O$1504,"Crediteuren",'Brondata'!$J$5:$J$1504,'Instellingen'!$D$8,'Brondata'!$K$5:$K$1504,"<="&'Instellingen'!$F$17) | D22: =-SUMIFS('Brondata'!$I$5:$I$1504,'Brondata'!$O$5:$O$1504,"Crediteuren",'Brondata'!$J$5:$J$1504,'Instellingen'!$D$12,'Brondata'!$K$5:$K$1504,"<="&'Instellingen'!$F$17) | E22: =C22-D22 | F22: =IFERROR((C22-D22)/ABS(D22),0)
B23: Overige schulden | C23: =-SUMIFS('Brondata'!$I$5:$I$1504,'Brondata'!$O$5:$O$1504,"Overige schulden",'Brondata'!$J$5:$J$1504,'Instellingen'!$D$8,'Brondata'!$K$5:$K$1504,"<="&'Instellingen'!$F$17) | D23: =-SUMIFS('Brondata'!$I$5:$I$1504,'Brondata'!$O$5:$O$1504,"Overige schulden",'Brondata'!$J$5:$J$1504,'Instellingen'!$D$12,'Brondata'!$K$5:$K$1504,"<="&'Instellingen'!$F$17) | E23: =C23-D23 | F23: =IFERROR((C23-D23)/ABS(D23),0)
B24: Totaal kortlopende schulden | C24: =C22+C23 | D24: =D22+D23 | E24: =C24-D24 | F24: =IFERROR((C24-D24)/ABS(D24),0)
B25: TOTAAL PASSIVA | C25: =C20+C21+C24 | D25: =D20+D21+D24 | E25: =C25-D25 | F25: =IFERROR((C25-D25)/ABS(D25),0)
B26: Balanscontrole (moet 0 zijn) | C26: =C17-C25 | D26: =D17-D25 | E26: =C26-D26 | F26: =IFERROR((C26-D26)/ABS(D26),0)

Sheet Ratios
A1: FINANCIËLE RATIO'S
A2: Start | C2: Dashboard | E2: Resultaat | G2: Balans | I2: Ratio's | K2: Debiteuren | M2: Crediteuren | O2: Voorraad | Q2: Trend | S2: Signalering | U2: Samenvatting
A3: =('Instellingen'!$D$6)&" · kengetallen t/m "&('Instellingen'!$D$17)&" "&('Instellingen'!$D$8) | I3: Annualisatie: | J3: =12/'Instellingen'!$F$17
B6: Kengetal | C6: Waarde | D6: Norm | E6: Status | F6: Toelichting
B7: Current ratio | C7: =IFERROR('Balans'!$C$16/'Balans'!$C$24,0) | D7: ='Instellingen'!$D$29 | E7: =IF(D7="-","—",IF(C7>=D7,"Goed",IF(C7>=0.9*D7,"Aandacht","Onder norm"))) | F7: Vlottende activa / kortlopende schulden
B8: Quick ratio | C8: =IFERROR(('Balans'!$C$16-'Balans'!$C$12)/'Balans'!$C$24,0) | D8: ='Instellingen'!$D$30 | E8: =IF(D8="-","—",IF(C8>=D8,"Goed",IF(C8>=0.9*D8,"Aandacht","Onder norm"))) | F8: (Vlottende activa -/- voorraad) / kortlopende schulden
B9: Solvabiliteit | C9: =IFERROR('Balans'!$C$20/'Balans'!$C$25,0) | D9: ='Instellingen'!$D$31 | E9: =IF(D9="-","—",IF(C9>=D9,"Goed",IF(C9>=0.9*D9,"Aandacht","Onder norm"))) | F9: Eigen vermogen / balanstotaal
B10: Rentabiliteit eigen vermogen | C10: =IFERROR('Resultatenrekening'!$C$21*'Ratios'!$J$3/'Balans'!$C$20,0) | D10: ='Instellingen'!$D$32 | E10: =IF(D10="-","—",IF(C10>=D10,"Goed",IF(C10>=0.9*D10,"Aandacht","Onder norm"))) | F10: Resultaat (geannualiseerd) / eigen vermogen
B11: Rentabiliteit totaal vermogen | C11: =IFERROR('Resultatenrekening'!$C$19*'Ratios'!$J$3/'Balans'!$C$17,0) | D11: - | E11: ="—" | F11: Bedrijfsresultaat (geann.) / totaal vermogen
B12: Brutomarge | C12: ='Resultatenrekening'!$C$24 | D12: ='Instellingen'!$D$27 | E12: =IF(D12="-","—",IF(C12>=D12,"Goed",IF(C12>=0.9*D12,"Aandacht","Onder norm"))) | F12: Brutowinst / omzet
B13: Nettomarge | C13: =IFERROR('Resultatenrekening'!$C$21/'Resultatenrekening'!$C$7,0) | D13: ='Instellingen'!$D$28 | E13: =IF(D13="-","—",IF(C13>=D13,"Goed",IF(C13>=0.9*D13,"Aandacht","Onder norm"))) | F13: Resultaat / omzet
B14: Voorraadrotatie | C14: =IFERROR('Resultatenrekening'!$C$8*'Ratios'!$J$3/(('Balans'!$C$12+'Balans'!$D$12)/2),0) | D14: ='Instellingen'!$D$33 | E14: =IF(D14="-","—",IF(C14>=D14,"Goed",IF(C14>=0.9*D14,"Aandacht","Onder norm"))) | F14: Inkoopwaarde (geann.) / gemiddelde voorraad
B15: Omloopsnelheid debiteuren (DSO) | C15: =IFERROR('Balans'!$C$13/('Resultatenrekening'!$C$7*'Ratios'!$J$3)*365,0) | D15: ='Instellingen'!$D$34 | E15: =IF(D15="-","—",IF(C15<=D15,"Goed",IF(C15<=1.1*D15,"Aandacht","Boven norm"))) | F15: Debiteuren / omzet × 365 dagen
B16: Omloopsnelheid crediteuren (DPO) | C16: =IFERROR('Balans'!$C$22/('Resultatenrekening'!$C$8*'Ratios'!$J$3)*365,0) | D16: ='Instellingen'!$D$35 | E16: =IF(D16="-","—",IF(C16<=D16,"Goed",IF(C16<=1.1*D16,"Aandacht","Boven norm"))) | F16: Crediteuren / inkoopwaarde × 365 dagen
B17: Werkkapitaal | C17: ='Balans'!$C$16-'Balans'!$C$24 | D17: ='Instellingen'!$D$36 | E17: =IF(D17="-","—",IF(C17>=D17,"Goed",IF(C17>=0.9*D17,"Aandacht","Onder norm"))) | F17: Vlottende activa -/- kortlopende schulden
B18: Cash conversion cycle | C18: =C15+IFERROR(365/C14,0)-C16 | D18: - | E18: =IF(D18="-","—",IF(C18<=D18,"Goed",IF(C18<=1.1*D18,"Aandacht","Boven norm"))) | F18: DSO + voorraaddagen -/- DPO
B19: Interest coverage ratio | C19: =IFERROR('Resultatenrekening'!$C$19/'Resultatenrekening'!$C$20,0) | D19: 4 | E19: =IF(D19="-","—",IF(C19>=D19,"Goed",IF(C19>=0.9*D19,"Aandacht","Onder norm"))) | F19: Bedrijfsresultaat / financiële lasten

Sheet Debiteuren
A1: DEBITEURENANALYSE
A2: Start | C2: Dashboard | E2: Resultaat | G2: Balans | I2: Ratio's | K2: Debiteuren | M2: Crediteuren | O2: Voorraad | Q2: Trend | S2: Signalering | U2: Samenvatting
A3: Openstaande posten, ouderdomsanalyse en top-debiteuren. Peildatum = rapportagedatum.
B5: Totaal openstaand | E5: Gem. betalingstermijn (DSO) | H5: Aantal openstaande posten | K5: % vervallen
B6: =SUM(F9:F21) | E6: ='Ratios'!$C$15 | H6: =COUNT(F9:F21) | K6: =IFERROR(SUMIFS(F9:F21,G9:G21,">0")/SUM(F9:F21),0)
B8: Factuurnr | C8: Debiteur | D8: Factuurdatum | E8: Vervaldatum | F8: Openstaand (€) | G8: Dagen te laat | H8: Ouderdom
B9: 2025-1180 | C9: Bouwgroep Jansen BV | D9: 45981 | E9: 46011 | F9: 92000 | G9: ='Instellingen'!$D$9-E9 | H9: =IF(G9<=0,"Niet vervallen",IF(G9<=30,"1-30 dgn",IF(G9<=60,"31-60 dgn",IF(G9<=90,"61-90 dgn",">90 dgn"))))
B10: 2025-1206 | C10: Bouwgroep Jansen BV | D10: 45996 | E10: 46026 | F10: 68000 | G10: ='Instellingen'!$D$9-E10 | H10: =IF(G10<=0,"Niet vervallen",IF(G10<=30,"1-30 dgn",IF(G10<=60,"31-60 dgn",IF(G10<=90,"61-90 dgn",">90 dgn"))))
B11: 2025-1210 | C11: Retail Noord NV | D11: 46001 | E11: 46031 | F11: 74000 | G11: ='Instellingen'!$D$9-E11 | H11: =IF(G11<=0,"Niet vervallen",IF(G11<=30,"1-30 dgn",IF(G11<=60,"31-60 dgn",IF(G11<=90,"61-90 dgn",">90 dgn"))))
B12: 2025-1015 | C12: Retail Noord NV | D12: 45945 | E12: 45975 | F12: 41000 | G12: ='Instellingen'!$D$9-E12 | H12: =IF(G12<=0,"Niet vervallen",IF(G12<=30,"1-30 dgn",IF(G12<=60,"31-60 dgn",IF(G12<=90,"61-90 dgn",">90 dgn"))))
B13: 2025-1201 | C13: TechniPro BV | D13: 45992 | E13: 46022 | F13: 55000 | G13: ='Instellingen'!$D$9-E13 | H13: =IF(G13<=0,"Niet vervallen",IF(G13<=30,"1-30 dgn",IF(G13<=60,"31-60 dgn",IF(G13<=90,"61-90 dgn",">90 dgn"))))
B14: 2025-1101 | C14: TechniPro BV | D14: 45962 | E14: 45992 | F14: 39000 | G14: ='Instellingen'!$D$9-E14 | H14: =IF(G14<=0,"Niet vervallen",IF(G14<=30,"1-30 dgn",IF(G14<=60,"31-60 dgn",IF(G14<=90,"61-90 dgn",">90 dgn"))))
B15: 2025-0920 | C15: De Vries Handel | D15: 45920 | E15: 45950 | F15: 28000 | G15: ='Instellingen'!$D$9-E15 | H15: =IF(G15<=0,"Niet vervallen",IF(G15<=30,"1-30 dgn",IF(G15<=60,"31-60 dgn",IF(G15<=90,"61-90 dgn",">90 dgn"))))
B16: 2025-1218 | C16: De Vries Handel | D16: 46009 | E16: 46039 | F16: 47000 | G16: ='Instellingen'!$D$9-E16 | H16: =IF(G16<=0,"Niet vervallen",IF(G16<=30,"1-30 dgn",IF(G16<=60,"31-60 dgn",IF(G16<=90,"61-90 dgn",">90 dgn"))))
B17: 2025-1212 | C17: Groothandel Zuid | D17: 46003 | E17: 46033 | F17: 63000 | G17: ='Instellingen'!$D$9-E17 | H17: =IF(G17<=0,"Niet vervallen",IF(G17<=30,"1-30 dgn",IF(G17<=60,"31-60 dgn",IF(G17<=90,"61-90 dgn",">90 dgn"))))
B18: 2025-1125 | C18: Groothandel Zuid | D18: 45986 | E18: 46016 | F18: 31000 | G18: ='Instellingen'!$D$9-E18 | H18: =IF(G18<=0,"Niet vervallen",IF(G18<=30,"1-30 dgn",IF(G18<=60,"31-60 dgn",IF(G18<=90,"61-90 dgn",">90 dgn"))))
B19: 2025-0830 | C19: Installatie Kort | D19: 45899 | E19: 45929 | F19: 18000 | G19: ='Instellingen'!$D$9-E19 | H19: =IF(G19<=0,"Niet vervallen",IF(G19<=30,"1-30 dgn",IF(G19<=60,"31-60 dgn",IF(G19<=90,"61-90 dgn",">90 dgn"))))
B20: 2025-1220 | C20: Installatie Kort | D20: 46011 | E20: 46041 | F20: 25000 | G20: ='Instellingen'!$D$9-E20 | H20: =IF(G20<=0,"Niet vervallen",IF(G20<=30,"1-30 dgn",IF(G20<=60,"31-60 dgn",IF(G20<=90,"61-90 dgn",">90 dgn"))))
B21: 2025-1208 | C21: Retail Noord NV | D21: 45999 | E21: 46029 | F21: 29000 | G21: ='Instellingen'!$D$9-E21 | H21: =IF(G21<=0,"Niet vervallen",IF(G21<=30,"1-30 dgn",IF(G21<=60,"31-60 dgn",IF(G21<=90,"61-90 dgn",">90 dgn"))))
B24: Ouderdomsanalyse | F24: Top debiteuren
B25: Ouderdom | C25: Bedrag | F25: Debiteur | G25: Openstaand
B26: Niet vervallen | C26: =SUMIFS(F9:F21,G9:G21,"<=0") | F26: Bouwgroep Jansen BV | G26: =SUMIF(C9:C21,F26,F9:F21)
B27: 1-30 dagen | C27: =SUMIFS(F9:F21,G9:G21,">0",G9:G21,"<=30") | F27: Retail Noord NV | G27: =SUMIF(C9:C21,F27,F9:F21)
B28: 31-60 dagen | C28: =SUMIFS(F9:F21,G9:G21,">30",G9:G21,"<=60") | F28: TechniPro BV | G28: =SUMIF(C9:C21,F28,F9:F21)
B29: 61-90 dagen | C29: =SUMIFS(F9:F21,G9:G21,">60",G9:G21,"<=90") | F29: De Vries Handel | G29: =SUMIF(C9:C21,F29,F9:F21)
B30: > 90 dagen | C30: =SUMIFS(F9:F21,G9:G21,">90") | F30: Groothandel Zuid | G30: =SUMIF(C9:C21,F30,F9:F21)
F31: Installatie Kort | G31: =SUMIF(C9:C21,F31,F9:F21)

Sheet Crediteuren
A1: CREDITEURENANALYSE
A2: Start | C2: Dashboard | E2: Resultaat | G2: Balans | I2: Ratio's | K2: Debiteuren | M2: Crediteuren | O2: Voorraad | Q2: Trend | S2: Signalering | U2: Samenvatting
A3: Openstaande posten, betaaltermijn en top-crediteuren. Peildatum = rapportagedatum.
B5: Totaal openstaand | E5: Gem. betaaltermijn (DPO) | H5: Aantal posten | K5: Grootste crediteur
B6: =SUM(F9:F16) | E6: ='Ratios'!$C$16 | H6: =COUNT(F9:F16) | K6: =INDEX(C9:C16,MATCH(MAX(F9:F16),F9:F16,0))
B8: Factuurnr | C8: Crediteur | D8: Factuurdatum | E8: Vervaldatum | F8: Openstaand (€) | G8: Dagen tot verval | H8: Ouderdom
B9: INK-2025-401 | C9: Importeur Wong Ltd | D9: 46002 | E9: 46032 | F9: 120000 | G9: =E9-'Instellingen'!$D$9 | H9: =IF(G9<0,"Vervallen",IF(G9<=15,"0-15 dgn",IF(G9<=30,"16-30 dgn",">30 dgn")))
B10: INK-2025-388 | C10: Importeur Wong Ltd | D10: 45989 | E10: 46019 | F10: 60000 | G10: =E10-'Instellingen'!$D$9 | H10: =IF(G10<0,"Vervallen",IF(G10<=15,"0-15 dgn",IF(G10<=30,"16-30 dgn",">30 dgn")))
B11: INK-2025-405 | C11: Logistiek Partners BV | D11: 45997 | E11: 46027 | F11: 55000 | G11: =E11-'Instellingen'!$D$9 | H11: =IF(G11<0,"Vervallen",IF(G11<=15,"0-15 dgn",IF(G11<=30,"16-30 dgn",">30 dgn")))
B12: INK-2025-372 | C12: Logistiek Partners BV | D12: 45976 | E12: 46006 | F12: 38000 | G12: =E12-'Instellingen'!$D$9 | H12: =IF(G12<0,"Vervallen",IF(G12<=15,"0-15 dgn",IF(G12<=30,"16-30 dgn",">30 dgn")))
B13: INK-2025-410 | C13: Verpakking Totaal | D13: 46007 | E13: 46037 | F13: 47000 | G13: =E13-'Instellingen'!$D$9 | H13: =IF(G13<0,"Vervallen",IF(G13<=15,"0-15 dgn",IF(G13<=30,"16-30 dgn",">30 dgn")))
B14: INK-2025-360 | C14: Energie Direct | D14: 45981 | E14: 46011 | F14: 22000 | G14: =E14-'Instellingen'!$D$9 | H14: =IF(G14<0,"Vervallen",IF(G14<=15,"0-15 dgn",IF(G14<=30,"16-30 dgn",">30 dgn")))
B15: INK-2025-408 | C15: Kantoor & Co | D15: 46000 | E15: 46030 | F15: 48000 | G15: =E15-'Instellingen'!$D$9 | H15: =IF(G15<0,"Vervallen",IF(G15<=15,"0-15 dgn",IF(G15<=30,"16-30 dgn",">30 dgn")))
B16: INK-2025-399 | C16: Verpakking Totaal | D16: 45991 | E16: 46021 | F16: 40000 | G16: =E16-'Instellingen'!$D$9 | H16: =IF(G16<0,"Vervallen",IF(G16<=15,"0-15 dgn",IF(G16<=30,"16-30 dgn",">30 dgn")))
F19: Top crediteuren
F20: Crediteur | G20: Openstaand
F21: Importeur Wong Ltd | G21: =SUMIF(C9:C16,F21,F9:F16)
F22: Logistiek Partners BV | G22: =SUMIF(C9:C16,F22,F9:F16)
F23: Verpakking Totaal | G23: =SUMIF(C9:C16,F23,F9:F16)
F24: Energie Direct | G24: =SUMIF(C9:C16,F24,F9:F16)
F25: Kantoor & Co | G25: =SUMIF(C9:C16,F25,F9:F16)

Sheet Voorraad
A1: VOORRAADANALYSE
A2: Start | C2: Dashboard | E2: Resultaat | G2: Balans | I2: Ratio's | K2: Debiteuren | M2: Crediteuren | O2: Voorraad | Q2: Trend | S2: Signalering | U2: Samenvatting
A3: =('Instellingen'!$D$6)&" · voorraadpositie t/m "&('Instellingen'!$D$17)&" "&('Instellingen'!$D$8)
B5: Voorraad (eind) | E5: Voorraadrotatie | H5: Voorraaddagen | K5: Gemiddelde voorraad
B6: ='Balans'!$C$12 | E6: ='Ratios'!$C$14 | H6: =IFERROR(365/'Ratios'!$C$14,0) | K6: =('Balans'!$C$12+'Balans'!$D$12)/2
B24: Signaleringen voorraad
B25: Signaal | D25: Waarde | E25: Referentie | F25: Status
B26: Voorraadgroei t.o.v. omzetgroei | D26: =IFERROR(('Balans'!$C$12-'Balans'!$D$12)/'Balans'!$D$12,0) | E26: =IFERROR(('Resultatenrekening'!$C$7-'Resultatenrekening'!$D$7)/'Resultatenrekening'!$D$7,0) | F26: =IF(IFERROR(('Balans'!$C$12-'Balans'!$D$12)/'Balans'!$D$12,0)<=IFERROR(('Resultatenrekening'!$C$7-'Resultatenrekening'!$D$7)/'Resultatenrekening'!$D$7,0),"Goed",IF(IFERROR(('Balans'!$C$12-'Balans'!$D$12)/'Balans'!$D$12,0)<=IFERROR(('Resultatenrekening'!$C$7-'Resultatenrekening'!$D$7)/'Resultatenrekening'!$D$7,0)+0.05,"Aandacht","Onder norm"))
B27: Voorraadrotatie t.o.v. norm | D27: ='Ratios'!$C$14 | E27: ='Instellingen'!$D$33 | F27: =IF('Ratios'!$C$14>='Instellingen'!$D$33,"Goed",IF('Ratios'!$C$14>=0.9*'Instellingen'!$D$33,"Aandacht","Onder norm"))

Sheet Trendanalyse
A1: TRENDANALYSE
A2: Start | C2: Dashboard | E2: Resultaat | G2: Balans | I2: Ratio's | K2: Debiteuren | M2: Crediteuren | O2: Voorraad | Q2: Trend | S2: Signalering | U2: Samenvatting
A3: Ontwikkeling over 24 maanden (2 boekjaren). Uitbreidbaar naar 36 maanden zodra meer historie in Brondata staat.
B35: Jaarvergelijking (t/m geselecteerde periode)
B36: Kengetal | C36: ='Instellingen'!$D$8 | D36: ='Instellingen'!$D$12 | E36: Verschil %
B37: Omzet | C37: ='Resultatenrekening'!$C$7 | D37: ='Resultatenrekening'!$D$7 | E37: =IFERROR((C37-D37)/ABS(D37),0)
B38: Brutowinst | C38: ='Resultatenrekening'!$C$9 | D38: ='Resultatenrekening'!$D$9 | E38: =IFERROR((C38-D38)/ABS(D38),0)
B39: Bedrijfsresultaat | C39: ='Resultatenrekening'!$C$19 | D39: ='Resultatenrekening'!$D$19 | E39: =IFERROR((C39-D39)/ABS(D39),0)
B40: Resultaat | C40: ='Resultatenrekening'!$C$21 | D40: ='Resultatenrekening'!$D$21 | E40: =IFERROR((C40-D40)/ABS(D40),0)
B41: Liquide middelen | C41: ='Balans'!$C$15 | D41: ='Balans'!$D$15 | E41: =IFERROR((C41-D41)/ABS(D41),0)
B42: Eigen vermogen | C42: ='Balans'!$C$20 | D42: ='Balans'!$D$20 | E42: =IFERROR((C42-D42)/ABS(D42),0)

Sheet Signalering
A1: SIGNALERINGSDASHBOARD
A2: Start | C2: Dashboard | E2: Resultaat | G2: Balans | I2: Ratio's | K2: Debiteuren | M2: Crediteuren | O2: Voorraad | Q2: Trend | S2: Signalering | U2: Samenvatting
A3: Automatische waarschuwingen op basis van de normeringen (Instellingen).
B6: Signaal | C6: Waarde | D6: Norm | E6: Status | F6: Advies
B7: Brutomarge onder norm | C7: ='Ratios'!$C$12 | D7: ='Ratios'!$D$12 | E7: =IF('Ratios'!$E$12="Goed","✓ In orde",IF('Ratios'!$E$12="Aandacht","! Let op","✗ Kritiek")) | F7: Bewaak inkoopprijzen en verkoopmarges.
B8: Nettomarge onder norm | C8: ='Ratios'!$C$13 | D8: ='Ratios'!$D$13 | E8: =IF('Ratios'!$E$13="Goed","✓ In orde",IF('Ratios'!$E$13="Aandacht","! Let op","✗ Kritiek")) | F8: Analyseer kostenstructuur en prijszetting.
B9: Solvabiliteit onvoldoende | C9: ='Ratios'!$C$9 | D9: ='Ratios'!$D$9 | E9: =IF('Ratios'!$E$9="Goed","✓ In orde",IF('Ratios'!$E$9="Aandacht","! Let op","✗ Kritiek")) | F9: Versterk eigen vermogen of los schulden af.
B10: Liquiditeit (current ratio) laag | C10: ='Ratios'!$C$7 | D10: ='Ratios'!$D$7 | E10: =IF('Ratios'!$E$7="Goed","✓ In orde",IF('Ratios'!$E$7="Aandacht","! Let op","✗ Kritiek")) | F10: Bewaak werkkapitaal en betaalgedrag.
B11: Werkkapitaal onder norm | C11: ='Ratios'!$C$17 | D11: ='Ratios'!$D$17 | E11: =IF('Ratios'!$E$17="Goed","✓ In orde",IF('Ratios'!$E$17="Aandacht","! Let op","✗ Kritiek")) | F11: Stuur op voorraden, debiteuren en crediteuren.
B12: Debiteurentermijn te hoog | C12: ='Ratios'!$C$15 | D12: ='Ratios'!$D$15 | E12: =IF('Ratios'!$E$15="Goed","✓ In orde",IF('Ratios'!$E$15="Aandacht","! Let op","✗ Kritiek")) | F12: Verscherp debiteurenbeheer en aanmaningen.
B13: Voorraadrotatie te laag | C13: ='Ratios'!$C$14 | D13: ='Ratios'!$D$14 | E13: =IF('Ratios'!$E$14="Goed","✓ In orde",IF('Ratios'!$E$14="Aandacht","! Let op","✗ Kritiek")) | F13: Verlaag incourante voorraad, verbeter inkoop.
B16: Legenda: ✓ In orde · ! Let op (binnen 10% van norm) · ✗ Kritiek (buiten norm)

Sheet Samenvatting
A1: MANAGEMENTSAMENVATTING
A2: Start | C2: Dashboard | E2: Resultaat | G2: Balans | I2: Ratio's | K2: Debiteuren | M2: Crediteuren | O2: Voorraad | Q2: Trend | S2: Signalering | U2: Samenvatting
A3: Automatisch gegenereerd op basis van de cijfers. Bespreekklaar voor het adviesgesprek.
B5: Kerncijfers
B6: ="De omzet t/m de geselecteerde periode bedraagt "&TEXT('Resultatenrekening'!$C$7,"€ #,##0")&" ("&TEXT(IFERROR(('Resultatenrekening'!$C$7-'Resultatenrekening'!$D$7)/'Resultatenrekening'!$D$7,0),"+0.0%;-0.0%")&" t.o.v. vorig jaar). De brutomarge is "&TEXT('Resultatenrekening'!$C$24,"0.0%")&" en het resultaat "&TEXT('Resultatenrekening'!$C$21,"€ #,##0")&"."
B7: ="Het eigen vermogen bedraagt "&TEXT('Balans'!$C$20,"€ #,##0")&" (solvabiliteit "&TEXT(IFERROR('Balans'!$C$20/'Balans'!$C$25,0),"0.0%")&"), de current ratio is "&TEXT(IFERROR('Balans'!$C$16/'Balans'!$C$24,0),"0.00")&" en het werkkapitaal "&TEXT('Balans'!$C$16-'Balans'!$C$24,"€ #,##0")&"."
B9: Sterke punten
B10: =IF('Resultatenrekening'!$C$24>='Instellingen'!$D$27,"• "&"Brutomarge boven norm ("&TEXT('Resultatenrekening'!$C$24,"0.0%")&").","")
B11: =IF(IFERROR('Balans'!$C$20/'Balans'!$C$25,0)>='Instellingen'!$D$31,"• "&"Solvabiliteit gezond ("&TEXT(IFERROR('Balans'!$C$20/'Balans'!$C$25,0),"0.0%")&").","")
B12: =IF(IFERROR('Balans'!$C$16/'Balans'!$C$24,0)>='Instellingen'!$D$29,"• "&"Voldoende liquiditeit (current ratio "&TEXT(IFERROR('Balans'!$C$16/'Balans'!$C$24,0),"0.00")&").","")
B13: =IF('Resultatenrekening'!$C$7>='Resultatenrekening'!$D$7,"• "&"Omzetgroei t.o.v. vorig jaar ("&TEXT(IFERROR(('Resultatenrekening'!$C$7-'Resultatenrekening'!$D$7)/'Resultatenrekening'!$D$7,0),"+0.0%")&").","")
B15: Risico's en aandachtspunten
B16: =IF('Resultatenrekening'!$C$24<'Instellingen'!$D$27,"• "&"Brutomarge onder norm ("&TEXT('Resultatenrekening'!$C$24,"0.0%")&" < "&TEXT('Instellingen'!$D$27,"0.0%")&").","")
B17: =IF(IFERROR('Balans'!$C$20/'Balans'!$C$25,0)<'Instellingen'!$D$31,"• "&"Solvabiliteit onder norm.","")
B18: =IF(IFERROR('Balans'!$C$16/'Balans'!$C$24,0)<'Instellingen'!$D$29,"• "&"Current ratio onder norm ("&TEXT(IFERROR('Balans'!$C$16/'Balans'!$C$24,0),"0.00")&").","")
B19: =IF(IFERROR('Balans'!$C$13/('Resultatenrekening'!$C$7*'Ratios'!$J$3)*365,0)>'Instellingen'!$D$34,"• "&"Debiteurentermijn te hoog ("&TEXT(IFERROR('Balans'!$C$13/('Resultatenrekening'!$C$7*'Ratios'!$J$3)*365,0),"0")&" dagen).","")
B20: =IF(IFERROR(('Balans'!$C$12-'Balans'!$D$12)/'Balans'!$D$12,0)>IFERROR(('Resultatenrekening'!$C$7-'Resultatenrekening'!$D$7)/'Resultatenrekening'!$D$7,0),"• "&"Voorraad groeit sneller dan de omzet.","")
B22: Adviespunten accountant
B23: "• Bespreek marge-ontwikkeling en kostenbeheersing met de ondernemer."
B24: =IF(IFERROR('Balans'!$C$13/('Resultatenrekening'!$C$7*'Ratios'!$J$3)*365,0)>'Instellingen'!$D$34,"• Verscherp het debiteurenbeheer om werkkapitaal vrij te maken.","• Continueer het huidige debiteurenbeheer.")
B25: =IF(IFERROR('Balans'!$C$20/'Balans'!$C$25,0)<'Instellingen'!$D$31,"• Werk aan versterking van het eigen vermogen (winstinhouding).","• Vermogenspositie is solide; benut ruimte voor investeringen.")
B26: "• Toets de normeringen periodiek en actualiseer de brondata per periode."

Sheet Calc
A1: Maand | B1: Jaar | C1: Mnd | D1: Omzet | E1: Inkoop | F1: Brutowinst | G1: Personeel | H1: Huisvesting | I1: Auto | J1: Verkoop | K1: Kantoor | L1: Algemeen | M1: Afschrijving | N1: Operationele kosten | O1: Bedrijfsresultaat | P1: Financieel | Q1: Resultaat | R1: Liquide | S1: Voorraad | T1: Debiteuren | U1: Crediteuren | V1: Eigen vermogen | W1: Ov. vorderingen | X1: Ov. schulden | Y1: Werkkapitaal | Z1: EBITDA | AA1: DSO | AB1: DPO | AC1: Cashflow
A2: jan-24 | B2: 2024 | C2: 1 | D2: =-SUMIFS('Brondata'!$I$5:$I$1504,'Brondata'!$O$5:$O$1504,"Omzet",'Brondata'!$J$5:$J$1504,$B2,'Brondata'!$K$5:$K$1504,$C2) | E2: =SUMIFS('Brondata'!$I$5:$I$1504,'Brondata'!$O$5:$O$1504,"Inkoopwaarde",'Brondata'!$J$5:$J$1504,$B2,'Brondata'!$K$5:$K$1504,$C2) | F2: =D2-E2 | G2: =SUMIFS('Brondata'!$I$5:$I$1504,'Brondata'!$O$5:$O$1504,"Personeelskosten",'Brondata'!$J$5:$J$1504,$B2,'Brondata'!$K$5:$K$1504,$C2) | H2: =SUMIFS('Brondata'!$I$5:$I$1504,'Brondata'!$O$5:$O$1504,"Huisvesting",'Brondata'!$J$5:$J$1504,$B2,'Brondata'!$K$5:$K$1504,$C2) | I2: =SUMIFS('Brondata'!$I$5:$I$1504,'Brondata'!$O$5:$O$1504,"Autokosten",'Brondata'!$J$5:$J$1504,$B2,'Brondata'!$K$5:$K$1504,$C2) | J2: =SUMIFS('Brondata'!$I$5:$I$1504,'Brondata'!$O$5:$O$1504,"Verkoopkosten",'Brondata'!$J$5:$J$1504,$B2,'Brondata'!$K$5:$K$1504,$C2) | K2: =SUMIFS('Brondata'!$I$5:$I$1504,'Brondata'!$O$5:$O$1504,"Kantoorkosten",'Brondata'!$J$5:$J$1504,$B2,'Brondata'!$K$5:$K$1504,$C2) | L2: =SUMIFS('Brondata'!$I$5:$I$1504,'Brondata'!$O$5:$O$1504,"Algemene kosten",'Brondata'!$J$5:$J$1504,$B2,'Brondata'!$K$5:$K$1504,$C2) | M2: =SUMIFS('Brondata'!$I$5:$I$1504,'Brondata'!$O$5:$O$1504,"Afschrijvingen",'Brondata'!$J$5:$J$1504,$B2,'Brondata'!$K$5:$K$1504,$C2) | N2: =SUM(G2:M2) | O2: =F2-N2 | P2: =SUMIFS('Brondata'!$I$5:$I$1504,'Brondata'!$O$5:$O$1504,"Financiele baten en lasten",'Brondata'!$J$5:$J$1504,$B2,'Brondata'!$K$5:$K$1504,$C2) | Q2: =O2-P2 | R2: =SUMIFS('Brondata'!$I$5:$I$1504,'Brondata'!$O$5:$O$1504,"Liquide middelen",'Brondata'!$J$5:$J$1504,$B2,'Brondata'!$K$5:$K$1504,"<="&$C2) | S2: =SUMIFS('Brondata'!$I$5:$I$1504,'Brondata'!$O$5:$O$1504,"Voorraden",'Brondata'!$J$5:$J$1504,$B2,'Brondata'!$K$5:$K$1504,"<="&$C2) | T2: =SUMIFS('Brondata'!$I$5:$I$1504,'Brondata'!$O$5:$O$1504,"Debiteuren",'Brondata'!$J$5:$J$1504,$B2,'Brondata'!$K$5:$K$1504,"<="&$C2) | U2: =-SUMIFS('Brondata'!$I$5:$I$1504,'Brondata'!$O$5:$O$1504,"Crediteuren",'Brondata'!$J$5:$J$1504,$B2,'Brondata'!$K$5:$K$1504,"<="&$C2) | V2: =-SUMIFS('Brondata'!$I$5:$I$1504,'Brondata'!$O$5:$O$1504,"Eigen vermogen",'Brondata'!$J$5:$J$1504,$B2,'Brondata'!$K$5:$K$1504,"<="&$C2) | W2: =SUMIFS('Brondata'!$I$5:$I$1504,'Brondata'!$O$5:$O$1504,"Overige vorderingen",'Brondata'!$J$5:$J$1504,$B2,'Brondata'!$K$5:$K$1504,"<="&$C2) | X2: =-SUMIFS('Brondata'!$I$5:$I$1504,'Brondata'!$O$5:$O$1504,"Overige schulden",'Brondata'!$J$5:$J$1504,$B2,'Brondata'!$K$5:$K$1504,"<="&$C2) | Y2: =S2+T2+R2+W2-(U2+X2) | Z2: =O2+M2 | AA2: =IFERROR(T2/(D2*12)*365,0) | AB2: =IFERROR(U2/(E2*12)*365,0) | AC2: =Q2+M2
A3: feb-24 | B3: 2024 | C3: 2 | D3: =-SUMIFS('Brondata'!$I$5:$I$1504,'Brondata'!$O$5:$O$1504,"Omzet",'Brondata'!$J$5:$J$1504,$B3,'Brondata'!$K$5:$K$1504,$C3) | E3: =SUMIFS('Brondata'!$I$5:$I$1504,'Brondata'!$O$5:$O$1504,"Inkoopwaarde",'Brondata'!$J$5:$J$1504,$B3,'Brondata'!$K$5:$K$1504,$C3) | F3: =D3-E3 | G3: =SUMIFS('Brondata'!$I$5:$I$1504,'Brondata'!$O$5:$O$1504,"Personeelskosten",'Brondata'!$J$5:$J$1504,$B3,'Brondata'!$K$5:$K$1504,$C3) | H3: =SUMIFS('Brondata'!$I$5:$I$1504,'Brondata'!$O$5:$O$1504,"Huisvesting",'Brondata'!$J$5:$J$1504,$B3,'Brondata'!$K$5:$K$1504,$C3) | I3: =SUMIFS('Brondata'!$I$5:$I$1504,'Brondata'!$O$5:$O$1504,"Autokosten",'Brondata'!$J$5:$J$1504,$B3,'Brondata'!$K$5:$K$1504,$C3) | J3: =SUMIFS('Brondata'!$I$5:$I$1504,'Brondata'!$O$5:$O$1504,"Verkoopkosten",'Brondata'!$J$5:$J$1504,$B3,'Brondata'!$K$5:$K$1504,$C3) | K3: =SUMIFS('Brondata'!$I$5:$I$1504,'Brondata'!$O$5:$O$1504,"Kantoorkosten",'Brondata'!$J$5:$J$1504,$B3,'Brondata'!$K$5:$K$1504,$C3) | L3: =SUMIFS('Brondata'!$I$5:$I$1504,'Brondata'!$O$5:$O$1504,"Algemene kosten",'Brondata'!$J$5:$J$1504,$B3,'Brondata'!$K$5:$K$1504,$C3) | M3: =SUMIFS('Brondata'!$I$5:$I$1504,'Brondata'!$O$5:$O$1504,"Afschrijvingen",'Brondata'!$J$5:$J$1504,$B3,'Brondata'!$K$5:$K$1504,$C3) | N3: =SUM(G3:M3) | O3: =F3-N3 | P3: =SUMIFS('Brondata'!$I$5:$I$1504,'Brondata'!$O$5:$O$1504,"Financiele baten en lasten",'Brondata'!$J$5:$J$1504,$B3,'Brondata'!$K$5:$K$1504,$C3) | Q3: =O3-P3 | R3: =SUMIFS('Brondata'!$I$5:$I$1504,'Brondata'!$O$5:$O$1504,"Liquide middelen",'Brondata'!$J$5:$J$1504,$B3,'Brondata'!$K$5:$K$1504,"<="&$C3) | S3: =SUMIFS('Brondata'!$I$5:$I$1504,'Brondata'!$O$5:$O$1504,"Voorraden",'Brondata'!$J$5:$J$1504,$B3,'Brondata'!$K$5:$K$1504,"<="&$C3) | T3: =SUMIFS('Brondata'!$I$5:$I$1504,'Brondata'!$O$5:$O$1504,"Debiteuren",'Brondata'!$J$5:$J$1504,$B3,'Brondata'!$K$5:$K$1504,"<="&$C3) | U3: =-SUMIFS('Brondata'!$I$5:$I$1504,'Brondata'!$O$5:$O$1504,"Crediteuren",'Brondata'!$J$5:$J$1504,$B3,'Brondata'!$K$5:$K$1504,"<="&$C3) | V3: =-SUMIFS('Brondata'!$I$5:$I$1504,'Brondata'!$O$5:$O$1504,"Eigen vermogen",'Brondata'!$J$5:$J$1504,$B3,'Brondata'!$K$5:$K$1504,"<="&$C3) | W3: =SUMIFS('Brondata'!$I$5:$I$1504,'Brondata'!$O$5:$O$1504,"Overige vorderingen",'Brondata'!$J$5:$J$1504,$B3,'Brondata'!$K$5:$K$1504,"<="&$C3) | X3: =-SUMIFS('Brondata'!$I$5:$I$1504,'Brondata'!$O$5:$O$1504,"Overige schulden",'Brondata'!$J$5:$J$1504,$B3,'Brondata'!$K$5:$K$1504,"<="&$C3) | Y3: =S3+T3+R3+W3-(U3+X3) | Z3: =O3+M3 | AA3: =IFERROR(T3/(D3*12)*365,0) | AB3: =IFERROR(U3/(E3*12)*365,0) | AC3: =Q3+M3-(Y3-Y2)
A4: mrt-24 | B4: 2024 | C4: 3 | D4: =-SUMIFS('Brondata'!$I$5:$I$1504,'Brondata'!$O$5:$O$1504,"Omzet",'Brondata'!$J$5:$J$1504,$B4,'Brondata'!$K$5:$K$1504,$C4) | E4: =SUMIFS('Brondata'!$I$5:$I$1504,'Brondata'!$O$5:$O$1504,"Inkoopwaarde",'Brondata'!$J$5:$J$1504,$B4,'Brondata'!$K$5:$K$1504,$C4) | F4: =D4-E4 | G4: =SUMIFS('Brondata'!$I$5:$I$1504,'Brondata'!$O$5:$O$1504,"Personeelskosten",'Brondata'!$J$5:$J$1504,$B4,'Brondata'!$K$5:$K$1504,$C4) | H4: =SUMIFS('Brondata'!$I$5:$I$1504,'Brondata'!$O$5:$O$1504,"Huisvesting",'Brondata'!$J$5:$J$1504,$B4,'Brondata'!$K$5:$K$1504,$C4) | I4: =SUMIFS('Brondata'!$I$5:$I$1504,'Brondata'!$O$5:$O$1504,"Autokosten",'Brondata'!$J$5:$J$1504,$B4,'Brondata'!$K$5:$K$1504,$C4) | J4: =SUMIFS('Brondata'!$I$5:$I$1504,'Brondata'!$O$5:$O$1504,"Verkoopkosten",'Brondata'!$J$5:$J$1504,$B4,'Brondata'!$K$5:$K$1504,$C4) | K4: =SUMIFS('Brondata'!$I$5:$I$1504,'Brondata'!$O$5:$O$1504,"Kantoorkosten",'Brondata'!$J$5:$J$1504,$B4,'Brondata'!$K$5:$K$1504,$C4) | L4: =SUMIFS('Brondata'!$I$5:$I$1504,'Brondata'!$O$5:$O$1504,"Algemene kosten",'Brondata'!$J$5:$J$1504,$B4,'Brondata'!$K$5:$K$1504,$C4) | M4: =SUMIFS('Brondata'!$I$5:$I$1504,'Brondata'!$O$5:$O$1504,"Afschrijvingen",'Brondata'!$J$5:$J$1504,$B4,'Brondata'!$K$5:$K$1504,$C4) | N4: =SUM(G4:M4) | O4: =F4-N4 | P4: =SUMIFS('Brondata'!$I$5:$I$1504,'Brondata'!$O$5:$O$1504,"Financiele baten en lasten",'Brondata'!$J$5:$J$1504,$B4,'Brondata'!$K$5:$K$1504,$C4) | Q4: =O4-P4 | R4: =SUMIFS('Brondata'!$I$5:$I$1504,'Brondata'!$O$5:$O$1504,"Liquide middelen",'Brondata'!$J$5:$J$1504,$B4,'Brondata'!$K$5:$K$1504,"<="&$C4) | S4: =SUMIFS('Brondata'!$I$5:$I$1504,'Brondata'!$O$5:$O$1504,"Voorraden",'Brondata'!$J$5:$J$1504,$B4,'Brondata'!$K$5:$K$1504,"<="&$C4) | T4: =SUMIFS('Brondata'!$I$5:$I$1504,'Brondata'!$O$5:$O$1504,"Debiteuren",'Brondata'!$J$5:$J$1504,$B4,'Brondata'!$K$5:$K$1504,"<="&$C4) | U4: =-SUMIFS('Brondata'!$I$5:$I$1504,'Brondata'!$O$5:$O$1504,"Crediteuren",'Brondata'!$J$5:$J$1504,$B4,'Brondata'!$K$5:$K$1504,"<="&$C4) | V4: =-SUMIFS('Brondata'!$I$5:$I$1504,'Brondata'!$O$5:$O$1504,"Eigen vermogen",'Brondata'!$J$5:$J$1504,$B4,'Brondata'!$K$5:$K$1504,"<="&$C4) | W4: =SUMIFS('Brondata'!$I$5:$I$1504,'Brondata'!$O$5:$O$1504,"Overige vorderingen",'Brondata'!$J$5:$J$1504,$B4,'Brondata'!$K$5:$K$1504,"<="&$C4) | X4: =-SUMIFS('Brondata'!$I$5:$I$1504,'Brondata'!$O$5:$O$1504,"Overige schulden",'Brondata'!$J$5:$J$1504,$B4,'Brondata'!$K$5:$K$1504,"<="&$C4) | Y4: =S4+T4+R4+W4-(U4+X4) | Z4: =O4+M4 | AA4: =IFERROR(T4/(D4*12)*365,0) | AB4: =IFERROR(U4/(E4*12)*365,0) | AC4: =Q4+M4-(Y4-Y3)
A5: apr-24 | B5: 2024 | C5: 4 | D5: =-SUMIFS('Brondata'!$I$5:$I$1504,'Brondata'!$O$5:$O$1504,"Omzet",'Brondata'!$J$5:$J$1504,$B5,'Brondata'!$K$5:$K$1504,$C5) | E5: =SUMIFS('Brondata'!$I$5:$I$1504,'Brondata'!$O$5:$O$1504,"Inkoopwaarde",'Brondata'!$J$5:$J$1504,$B5,'Brondata'!$K$5:$K$1504,$C5) | F5: =D5-E5 | G5: =SUMIFS('Brondata'!$I$5:$I$1504,'Brondata'!$O$5:$O$1504,"Personeelskosten",'Brondata'!$J$5:$J$1504,$B5,'Brondata'!$K$5:$K$1504,$C5) | H5: =SUMIFS('Brondata'!$I$5:$I$1504,'Brondata'!$O$5:$O$1504,"Huisvesting",'Brondata'!$J$5:$J$1504,$B5,'Brondata'!$K$5:$K$1504,$C5) | I5: =SUMIFS('Brondata'!$I$5:$I$1504,'Brondata'!$O$5:$O$1504,"Autokosten",'Brondata'!$J$5:$J$1504,$B5,'Brondata'!$K$5:$K$1504,$C5) | J5: =SUMIFS('Brondata'!$I$5:$I$1504,'Brondata'!$O$5:$O$1504,"Verkoopkosten",'Brondata'!$J$5:$J$1504,$B5,'Brondata'!$K$5:$K$1504,$C5) | K5: =SUMIFS('Brondata'!$I$5:$I$1504,'Brondata'!$O$5:$O$1504,"Kantoorkosten",'Brondata'!$J$5:$J$1504,$B5,'Brondata'!$K$5:$K$1504,$C5) | L5: =SUMIFS('Brondata'!$I$5:$I$1504,'Brondata'!$O$5:$O$1504,"Algemene kosten",'Brondata'!$J$5:$J$1504,$B5,'Brondata'!$K$5:$K$1504,$C5) | M5: =SUMIFS('Brondata'!$I$5:$I$1504,'Brondata'!$O$5:$O$1504,"Afschrijvingen",'Brondata'!$J$5:$J$1504,$B5,'Brondata'!$K$5:$K$1504,$C5) | N5: =SUM(G5:M5) | O5: =F5-N5 | P5: =SUMIFS('Brondata'!$I$5:$I$1504,'Brondata'!$O$5:$O$1504,"Financiele baten en lasten",'Brondata'!$J$5:$J$1504,$B5,'Brondata'!$K$5:$K$1504,$C5) | Q5: =O5-P5 | R5: =SUMIFS('Brondata'!$I$5:$I$1504,'Brondata'!$O$5:$O$1504,"Liquide middelen",'Brondata'!$J$5:$J$1504,$B5,'Brondata'!$K$5:$K$1504,"<="&$C5) | S5: =SUMIFS('Brondata'!$I$5:$I$1504,'Brondata'!$O$5:$O$1504,"Voorraden",'Brondata'!$J$5:$J$1504,$B5,'Brondata'!$K$5:$K$1504,"<="&$C5) | T5: =SUMIFS('Brondata'!$I$5:$I$1504,'Brondata'!$O$5:$O$1504,"Debiteuren",'Brondata'!$J$5:$J$1504,$B5,'Brondata'!$K$5:$K$1504,"<="&$C5) | U5: =-SUMIFS('Brondata'!$I$5:$I$1504,'Brondata'!$O$5:$O$1504,"Crediteuren",'Brondata'!$J$5:$J$1504,$B5,'Brondata'!$K$5:$K$1504,"<="&$C5) | V5: =-SUMIFS('Brondata'!$I$5:$I$1504,'Brondata'!$O$5:$O$1504,"Eigen vermogen",'Brondata'!$J$5:$J$1504,$B5,'Brondata'!$K$5:$K$1504,"<="&$C5) | W5: =SUMIFS('Brondata'!$I$5:$I$1504,'Brondata'!$O$5:$O$1504,"Overige vorderingen",'Brondata'!$J$5:$J$1504,$B5,'Brondata'!$K$5:$K$1504,"<="&$C5) | X5: =-SUMIFS('Brondata'!$I$5:$I$1504,'Brondata'!$O$5:$O$1504,"Overige schulden",'Brondata'!$J$5:$J$1504,$B5,'Brondata'!$K$5:$K$1504,"<="&$C5) | Y5: =S5+T5+R5+W5-(U5+X5) | Z5: =O5+M5 | AA5: =IFERROR(T5/(D5*12)*365,0) | AB5: =IFERROR(U5/(E5*12)*365,0) | AC5: =Q5+M5-(Y5-Y4)
A6: mei-24 | B6: 2024 | C6: 5 | D6: =-SUMIFS('Brondata'!$I$5:$I$1504,'Brondata'!$O$5:$O$1504,"Omzet",'Brondata'!$J$5:$J$1504,$B6,'Brondata'!$K$5:$K$1504,$C6) | E6: =SUMIFS('Brondata'!$I$5:$I$1504,'Brondata'!$O$5:$O$1504,"Inkoopwaarde",'Brondata'!$J$5:$J$1504,$B6,'Brondata'!$K$5:$K$1504,$C6) | F6: =D6-E6 | G6: =SUMIFS('Brondata'!$I$5:$I$1504,'Brondata'!$O$5:$O$1504,"Personeelskosten",'Brondata'!$J$5:$J$1504,$B6,'Brondata'!$K$5:$K$1504,$C6) | H6: =SUMIFS('Brondata'!$I$5:$I$1504,'Brondata'!$O$5:$O$1504,"Huisvesting",'Brondata'!$J$5:$J$1504,$B6,'Brondata'!$K$5:$K$1504,$C6) | I6: =SUMIFS('Brondata'!$I$5:$I$1504,'Brondata'!$O$5:$O$1504,"Autokosten",'Brondata'!$J$5:$J$1504,$B6,'Brondata'!$K$5:$K$1504,$C6) | J6: =SUMIFS('Brondata'!$I$5:$I$1504,'Brondata'!$O$5:$O$1504,"Verkoopkosten",'Brondata'!$J$5:$J$1504,$B6,'Brondata'!$K$5:$K$1504,$C6) | K6: =SUMIFS('Brondata'!$I$5:$I$1504,'Brondata'!$O$5:$O$1504,"Kantoorkosten",'Brondata'!$J$5:$J$1504,$B6,'Brondata'!$K$5:$K$1504,$C6) | L6: =SUMIFS('Brondata'!$I$5:$I$1504,'Brondata'!$O$5:$O$1504,"Algemene kosten",'Brondata'!$J$5:$J$1504,$B6,'Brondata'!$K$5:$K$1504,$C6) | M6: =SUMIFS('Brondata'!$I$5:$I$1504,'Brondata'!$O$5:$O$1504,"Afschrijvingen",'Brondata'!$J$5:$J$1504,$B6,'Brondata'!$K$5:$K$1504,$C6) | N6: =SUM(G6:M6) | O6: =F6-N6 | P6: =SUMIFS('Brondata'!$I$5:$I$1504,'Brondata'!$O$5:$O$1504,"Financiele baten en lasten",'Brondata'!$J$5:$J$1504,$B6,'Brondata'!$K$5:$K$1504,$C6) | Q6: =O6-P6 | R6: =SUMIFS('Brondata'!$I$5:$I$1504,'Brondata'!$O$5:$O$1504,"Liquide middelen",'Brondata'!$J$5:$J$1504,$B6,'Brondata'!$K$5:$K$1504,"<="&$C6) | S6: =SUMIFS('Brondata'!$I$5:$I$1504,'Brondata'!$O$5:$O$1504,"Voorraden",'Brondata'!$J$5:$J$1504,$B6,'Brondata'!$K$5:$K$1504,"<="&$C6) | T6: =SUMIFS('Brondata'!$I$5:$I$1504,'Brondata'!$O$5:$O$1504,"Debiteuren",'Brondata'!$J$5:$J$1504,$B6,'Brondata'!$K$5:$K$1504,"<="&$C6) | U6: =-SUMIFS('Brondata'!$I$5:$I$1504,'Brondata'!$O$5:$O$1504,"Crediteuren",'Brondata'!$J$5:$J$1504,$B6,'Brondata'!$K$5:$K$1504,"<="&$C6) | V6: =-SUMIFS('Brondata'!$I$5:$I$1504,'Brondata'!$O$5:$O$1504,"Eigen vermogen",'Brondata'!$J$5:$J$1504,$B6,'Brondata'!$K$5:$K$1504,"<="&$C6) | W6: =SUMIFS('Brondata'!$I$5:$I$1504,'Brondata'!$O$5:$O$1504,"Overige vorderingen",'Brondata'!$J$5:$J$1504,$B6,'Brondata'!$K$5:$K$1504,"<="&$C6) | X6: =-SUMIFS('Brondata'!$I$5:$I$1504,'Brondata'!$O$5:$O$1504,"Overige schulden",'Brondata'!$J$5:$J$1504,$B6,'Brondata'!$K$5:$K$1504,"<="&$C6) | Y6: =S6+T6+R6+W6-(U6+X6) | Z6: =O6+M6 | AA6: =IFERROR(T6/(D6*12)*365,0) | AB6: =IFERROR(U6/(E6*12)*365,0) | AC6: =Q6+M6-(Y6-Y5)
A7: jun-24 | B7: 2024 | C7: 6 | D7: =-SUMIFS('Brondata'!$I$5:$I$1504,'Brondata'!$O$5:$O$1504,"Omzet",'Brondata'!$J$5:$J$1504,$B7,'Brondata'!$K$5:$K$1504,$C7) | E7: =SUMIFS('Brondata'!$I$5:$I$1504,'Brondata'!$O$5:$O$1504,"Inkoopwaarde",'Brondata'!$J$5:$J$1504,$B7,'Brondata'!$K$5:$K$1504,$C7) | F7: =D7-E7 | G7: =SUMIFS('Brondata'!$I$5:$I$1504,'Brondata'!$O$5:$O$1504,"Personeelskosten",'Brondata'!$J$5:$J$1504,$B7,'Brondata'!$K$5:$K$1504,$C7) | H7: =SUMIFS('Brondata'!$I$5:$I$1504,'Brondata'!$O$5:$O$1504,"Huisvesting",'Brondata'!$J$5:$J$1504,$B7,'Brondata'!$K$5:$K$1504,$C7) | I7: =SUMIFS('Brondata'!$I$5:$I$1504,'Brondata'!$O$5:$O$1504,"Autokosten",'Brondata'!$J$5:$J$1504,$B7,'Brondata'!$K$5:$K$1504,$C7) | J7: =SUMIFS('Brondata'!$I$5:$I$1504,'Brondata'!$O$5:$O$1504,"Verkoopkosten",'Brondata'!$J$5:$J$1504,$B7,'Brondata'!$K$5:$K$1504,$C7) | K7: =SUMIFS('Brondata'!$I$5:$I$1504,'Brondata'!$O$5:$O$1504,"Kantoorkosten",'Brondata'!$J$5:$J$1504,$B7,'Brondata'!$K$5:$K$1504,$C7) | L7: =SUMIFS('Brondata'!$I$5:$I$1504,'Brondata'!$O$5:$O$1504,"Algemene kosten",'Brondata'!$J$5:$J$1504,$B7,'Brondata'!$K$5:$K$1504,$C7) | M7: =SUMIFS('Brondata'!$I$5:$I$1504,'Brondata'!$O$5:$O$1504,"Afschrijvingen",'Brondata'!$J$5:$J$1504,$B7,'Brondata'!$K$5:$K$1504,$C7) | N7: =SUM(G7:M7) | O7: =F7-N7 | P7: =SUMIFS('Brondata'!$I$5:$I$1504,'Brondata'!$O$5:$O$1504,"Financiele baten en lasten",'Brondata'!$J$5:$J$1504,$B7,'Brondata'!$K$5:$K$1504,$C7) | Q7: =O7-P7 | R7: =SUMIFS('Brondata'!$I$5:$I$1504,'Brondata'!$O$5:$O$1504,"Liquide middelen",'Brondata'!$J$5:$J$1504,$B7,'Brondata'!$K$5:$K$1504,"<="&$C7) | S7: =SUMIFS('Brondata'!$I$5:$I$1504,'Brondata'!$O$5:$O$1504,"Voorraden",'Brondata'!$J$5:$J$1504,$B7,'Brondata'!$K$5:$K$1504,"<="&$C7) | T7: =SUMIFS('Brondata'!$I$5:$I$1504,'Brondata'!$O$5:$O$1504,"Debiteuren",'Brondata'!$J$5:$J$1504,$B7,'Brondata'!$K$5:$K$1504,"<="&$C7) | U7: =-SUMIFS('Brondata'!$I$5:$I$1504,'Brondata'!$O$5:$O$1504,"Crediteuren",'Brondata'!$J$5:$J$1504,$B7,'Brondata'!$K$5:$K$1504,"<="&$C7) | V7: =-SUMIFS('Brondata'!$I$5:$I$1504,'Brondata'!$O$5:$O$1504,"Eigen vermogen",'Brondata'!$J$5:$J$1504,$B7,'Brondata'!$K$5:$K$1504,"<="&$C7) | W7: =SUMIFS('Brondata'!$I$5:$I$1504,'Brondata'!$O$5:$O$1504,"Overige vorderingen",'Brondata'!$J$5:$J$1504,$B7,'Brondata'!$K$5:$K$1504,"<="&$C7) | X7: =-SUMIFS('Brondata'!$I$5:$I$1504,'Brondata'!$O$5:$O$1504,"Overige schulden",'Brondata'!$J$5:$J$1504,$B7,'Brondata'!$K$5:$K$1504,"<="&$C7) | Y7: =S7+T7+R7+W7-(U7+X7) | Z7: =O7+M7 | AA7: =IFERROR(T7/(D7*12)*365,0) | AB7: =IFERROR(U7/(E7*12)*365,0) | AC7: =Q7+M7-(Y7-Y6)
